<?xml version="1.0" ?>
<!-- =================================================================================== -->
<!-- |    This document was autogenerated by xacro from rm_gimbal.urdf.xacro           | -->
<!-- |    EDITING THIS FILE BY HAND IS NOT RECOMMENDED                                 | -->
<!-- =================================================================================== -->
<robot name="rm_gimbal">
  <link name="odom"/>
  <link name="gimbal_link"/>
  <joint name="gimbal_joint" type="floating">
    <parent link="odom"/>
    <child link="gimbal_link"/>
  </joint>
  <link name="camera_link"/>
  <joint name="camera_joint" type="fixed">
    <origin rpy="0 0 0" xyz="0.10 0 0.05"/>
    <parent link="gimbal_link"/>
    <child link="camera_link"/>
    <axis xyz="0 0 0"/>
  </joint>
  <link name="camera_optical_frame"/>
  <joint name="camera_optical_joint" type="fixed">
    <origin rpy="-1.5707963267948966 0 -1.5707963267948966" xyz="0 0 0"/>
    <parent link="camera_link"/>
    <child link="camera_optical_frame"/>
  </joint>
</robot>
